Workbook

Sheet Method
B1: October 2026 bag targets — how each number is calculated
B2: Source data: Odoo (sales_pos_target, POS sales, Corporate invoices, stock). Built by lib/product_targets.py; spec docs/product-targets.md.
B4: 1. Total to share out
B5: The month's Odoo targets for every shop till (all 19, incl. Dar-es-Salaam and Uganda) plus Corporate, in bags. See the Inputs sheet.
B6: 2. Sales in the base period (the three complete months before: 1 Jul – 30 Sep 2026)
B7: Bags sold on every till + Corporate invoices; combo contents count per bag; refunds netted; delivery, straps, customisation, samples, discounts and gift bags left out. Colours fold into the bag (all Jumbo colours = JUMBO).
B8: 3. Days available — so new bags and stock-outs aren't penalised
B9: Days the bag had stock in a shop (any colour; daily stock rebuilt from Odoo's stock moves) or sold, counted from its launch (first sale ever). Days used = at least the minimum (Inputs) and at most the days in the period.
B10: 4. Full-period equivalent
B11: Full-period equivalent = period sold ÷ days used × days in the period. A bag in stock all period keeps its actual sales.
B12: 5. Share and target
B13: Share = the bag's full-period equivalent ÷ the sum over all bags. Raw target = share × total.
... B18: Worked example — the JUMBO row of the Bag targets sheet (live formulas)
B19: Sold Jul–Sep | C19: ='Bag targets'!G3 -> 3672
B20: Days used | C20: ='Bag targets'!I3 -> 92
B21: Full-period equivalent (sold ÷ days used × days in period) | C21: ='Bag targets'!J3 -> 3672
B22: Share of all bags | C22: ='Bag targets'!K3 -> 0.072645447
B23: × Total (Inputs) | C23: =Inputs!$C$4 -> 28013
B24: Raw target (share × total) | C24: ='Bag targets'!L3 -> 2035.0169
B25: October target (after rounding) | C25: ='Bag targets'!N3 -> 2035

Sheet Inputs
A1: Inputs — October 2026
A3: Item | C3: Value | E3: Source / note
A4: Total target (bags) | C4: =SUM(C15:C40) -> 28013 | E4: Sum of the till + Corporate targets below
A5: Base period start | C5: 46204 | E5: The three complete months before October
A6: Base period end | C6: 46295
A7: Days in base period | C7: =C6-C5+1 -> 92
A8: Minimum days available | C8: 14 | E8: Stops a bag a few days old from getting an inflated rate (lib/product_targets.MIN_DAYS)
A9: Total target (KES) | C9: =SUM(D15:D40) -> 56030805
A13: Odoo monthly targets — October 2026 (sales_pos_target)
A14: Till | B14: Scope | C14: Target (bags) | D14: Target (KES)
A15: HILTON | B15: pos | C15: 6342 | D15: 12683827
A16: KTDA Shop | B16: pos | C16: 2537 | D16: 5073531
A17: WEBSITE SALES | B17: pos | C17: 1903 | D17: 3805148
A18: STARMALL | B18: pos | C18: 1881 | D18: 3762869
A19: MOMBASA | B19: pos | C19: 1585 | D19: 3170957
A20: NAKURU | B20: pos | C20: 1427 | D20: 2853861
A21: ELDORET | B21: pos | C21: 1427 | D21: 2853861
A22: HAZINA | B22: pos | C22: 1374 | D22: 2748162
A23: THIKA | B23: pos | C23: 1374 | D23: 2748162
A24: KISUMU | B24: pos | C24: 951 | D24: 1902574
A25: MERU | B25: pos | C25: 898 | D25: 1796875
A26: KISII | B26: pos | C26: 792 | D26: 1585478
... A34: CORPORATE | B34: corporate | C34: 1163 | D34: 2325368
A36: Source: Odoo sales_pos_target, period = month, start 2026-10-01, scopes pos + corporate (pulled 2026-10-04).

Sheet Bag targets
A1: October 2026 — bag targets (blue = Odoo inputs, black = formulas; see Method)
A2: Bag | B2: Launch (first sale) | C2: Days with stock or sales | D2: Jul sold | E2: Aug sold | F2: Sep sold | G2: Period sold | H2: Days in shops (from launch) | I2: Days used | J2: Full-period equivalent | K2: Share | L2: Raw target | M2: Rounding +1 | N2: October target (bags) | O2: Sheet target (col C) | P2: Target − sheet | X2: Fraction (helper)
A3: JUMBO | C3: 92 | D3: 1315 | E3: 1341 | F3: 1016 | G3: =SUM(D3:F3) -> 3672 | H3: =C3 -> 92 | I3: =MIN(MAX(H3,Inputs!$C$8),Inputs!$C$7) -> 92 | J3: =IF(I3>0,G3/I3*Inputs!$C$7,0) -> 3672 | K3: =J3/SUM($J$3:$J$141) -> 0.072645447 | L3: =K3*Inputs!$C$4 -> 2035.0169 | M3: =IF(RANK(L3-INT(L3),$X$3:$X$141)+COUNTIF($X$3:X3,L3-INT(L3))-1<=Inputs!$C$4-SUMPRODUCT(INT($L$3:$L$141)),1,0) -> 0 | N3: =INT(L3)+M3 -> 2035 | O3: 2421 | P3: =IF(O3="","",N3-O3) -> -386 | X3: =L3-INT(L3) -> 0.016908252
A4: ANTITHEFT | C4: 92 | D4: 1252 | E4: 1043 | F4: 1335 | G4: =SUM(D4:F4) -> 3630 | H4: =C4 -> 92 | I4: =MIN(MAX(H4,Inputs!$C$8),Inputs!$C$7) -> 92 | J4: =IF(I4>0,G4/I4*Inputs!$C$7,0) -> 3630 | K4: =J4/SUM($J$3:$J$141) -> 0.071814535 | L4: =K4*Inputs!$C$4 -> 2011.7406 | M4: =IF(RANK(L4-INT(L4),$X$3:$X$141)+COUNTIF($X$3:X4,L4-INT(L4))-1<=Inputs!$C$4-SUMPRODUCT(INT($L$3:$L$141)),1,0) -> 1 | N4: =INT(L4)+M4 -> 2012 | O4: 1333 | P4: =IF(O4="","",N4-O4) -> 679 | X4: =L4-INT(L4) -> 0.74057107
A5: CODE 3 | C5: 92 | D5: 818 | E5: 1187 | F5: 809 | G5: =SUM(D5:F5) -> 2814 | H5: =C5 -> 92 | I5: =MIN(MAX(H5,Inputs!$C$8),Inputs!$C$7) -> 92 | J5: =IF(I5>0,G5/I5*Inputs!$C$7,0) -> 2814 | K5: =J5/SUM($J$3:$J$141) -> 0.055671102 | L5: =K5*Inputs!$C$4 -> 1559.5146 | M5: =IF(RANK(L5-INT(L5),$X$3:$X$141)+COUNTIF($X$3:X5,L5-INT(L5))-1<=Inputs!$C$4-SUMPRODUCT(INT($L$3:$L$141)),1,0) -> 0 | N5: =INT(L5)+M5 -> 1559 | O5: 1667 | P5: =IF(O5="","",N5-O5) -> -108 | X5: =L5-INT(L5) -> 0.51459145
A6: MAN BAG | C6: 92 | D6: 939 | E6: 628 | F6: 1125 | G6: =SUM(D6:F6) -> 2692 | H6: =C6 -> 92 | I6: =MIN(MAX(H6,Inputs!$C$8),Inputs!$C$7) -> 92 | J6: =IF(I6>0,G6/I6*Inputs!$C$7,0) -> 2692 | K6: =J6/SUM($J$3:$J$141) -> 0.053257501 | L6: =K6*Inputs!$C$4 -> 1491.9024 | M6: =IF(RANK(L6-INT(L6),$X$3:$X$141)+COUNTIF($X$3:X6,L6-INT(L6))-1<=Inputs!$C$4-SUMPRODUCT(INT($L$3:$L$141)),1,0) -> 1 | N6: =INT(L6)+M6 -> 1492 | O6: 1723 | P6: =IF(O6="","",N6-O6) -> -231 | X6: =L6-INT(L6) -> 0.90237391
A7: FABELA | C7: 92 | D7: 593 | E7: 650 | F7: 477 | G7: =SUM(D7:F7) -> 1720 | H7: =C7 -> 92 | I7: =MIN(MAX(H7,Inputs!$C$8),Inputs!$C$7) -> 92 | J7: =IF(I7>0,G7/I7*Inputs!$C$7,0) -> 1720 | K7: =J7/SUM($J$3:$J$141) -> 0.034027824 | L7: =K7*Inputs!$C$4 -> 953.22143 | M7: =IF(RANK(L7-INT(L7),$X$3:$X$141)+COUNTIF($X$3:X7,L7-INT(L7))-1<=Inputs!$C$4-SUMPRODUCT(INT($L$3:$L$141)),1,0) -> 0 | N7: =INT(L7)+M7 -> 953 | O7: 722 | P7: =IF(O7="","",N7-O7) -> 231 | X7: =L7-INT(L7) -> 0.22142761
A8: TRAVEL | C8: 92 | D8: 407 | E8: 620 | F8: 592 | G8: =SUM(D8:F8) -> 1619 | H8: =C8 -> 92 | I8: =MIN(MAX(H8,Inputs!$C$8),Inputs!$C$7) -> 92 | J8: =IF(I8>0,G8/I8*Inputs!$C$7,0) -> 1619 | K8: =J8/SUM($J$3:$J$141) -> 0.032029678 | L8: =K8*Inputs!$C$4 -> 897.24738 | M8: =IF(RANK(L8-INT(L8),$X$3:$X$141)+COUNTIF($X$3:X8,L8-INT(L8))-1<=Inputs!$C$4-SUMPRODUCT(INT($L$3:$L$141)),1,0) -> 0 | N8: =INT(L8)+M8 -> 897 | O8: 1084 | P8: =IF(O8="","",N8-O8) -> -187 | X8: =L8-INT(L8) -> 0.24737867
A9: PRIME | C9: 92 | D9: 375 | E9: 581 | F9: 356 | G9: =SUM(D9:F9) -> 1312 | H9: =C9 -> 92 | I9: =MIN(MAX(H9,Inputs!$C$8),Inputs!$C$7) -> 92 | J9: =IF(I9>0,G9/I9*Inputs!$C$7,0) -> 1312 | K9: =J9/SUM($J$3:$J$141) -> 0.025956107 | L9: =K9*Inputs!$C$4 -> 727.10844 | M9: =IF(RANK(L9-INT(L9),$X$3:$X$141)+COUNTIF($X$3:X9,L9-INT(L9))-1<=Inputs!$C$4-SUMPRODUCT(INT($L$3:$L$141)),1,0) -> 0 | N9: =INT(L9)+M9 -> 727 | O9: 667 | P9: =IF(O9="","",N9-O9) -> 60 | X9: =L9-INT(L9) -> 0.10843781
A10: BIG MAN BAG | C10: 92 | D10: 459 | E10: 338 | F10: 460 | G10: =SUM(D10:F10) -> 1257 | H10: =C10 -> 92 | I10: =MIN(MAX(H10,Inputs!$C$8),Inputs!$C$7) -> 92 | J10: =IF(I10>0,G10/I10*Inputs!$C$7,0) -> 1257 | K10: =J10/SUM($J$3:$J$141) -> 0.024868008 | L10: =K10*Inputs!$C$4 -> 696.62752 | M10: =IF(RANK(L10-INT(L10),$X$3:$X$141)+COUNTIF($X$3:X10,L10-INT(L10))-1<=Inputs!$C$4-SUMPRODUCT(INT($L$3:$L$141)),1,0) -> 1 | N10: =INT(L10)+M10 -> 697 | O10: 500 | P10: =IF(O10="","",N10-O10) -> 197 | X10: =L10-INT(L10) -> 0.62752006
A11: NIZANA | C11: 92 | D11: 494 | E11: 326 | F11: 381 | G11: =SUM(D11:F11) -> 1201 | H11: =C11 -> 92 | I11: =MIN(MAX(H11,Inputs!$C$8),Inputs!$C$7) -> 92 | J11: =IF(I11>0,G11/I11*Inputs!$C$7,0) -> 1201 | K11: =J11/SUM($J$3:$J$141) -> 0.023760126 | L11: =K11*Inputs!$C$4 -> 665.5924 | M11: =IF(RANK(L11-INT(L11),$X$3:$X$141)+COUNTIF($X$3:X11,L11-INT(L11))-1<=Inputs!$C$4-SUMPRODUCT(INT($L$3:$L$141)),1,0) -> 1 | N11: =INT(L11)+M11 -> 666 | O11: 444 | P11: =IF(O11="","",N11-O11) -> 222 | X11: =L11-INT(L11) -> 0.59240382
A12: MINI MAYA | C12: 92 | D12: 189 | E12: 387 | F12: 577 | G12: =SUM(D12:F12) -> 1153 | H12: =C12 -> 92 | I12: =MIN(MAX(H12,Inputs!$C$8),Inputs!$C$7) -> 92 | J12: =IF(I12>0,G12/I12*Inputs!$C$7,0) -> 1153 | K12: =J12/SUM($J$3:$J$141) -> 0.022810512 | L12: =K12*Inputs!$C$4 -> 638.99088 | M12: =IF(RANK(L12-INT(L12),$X$3:$X$141)+COUNTIF($X$3:X12,L12-INT(L12))-1<=Inputs!$C$4-SUMPRODUCT(INT($L$3:$L$141)),1,0) -> 1 | N12: =INT(L12)+M12 -> 639 | O12: 278 | P12: =IF(O12="","",N12-O12) -> 361 | X12: =L12-INT(L12) -> 0.9908756
A13: MEGA | C13: 92 | D13: 393 | E13: 414 | F13: 327 | G13: =SUM(D13:F13) -> 1134 | H13: =C13 -> 92 | I13: =MIN(MAX(H13,Inputs!$C$8),Inputs!$C$7) -> 92 | J13: =IF(I13>0,G13/I13*Inputs!$C$7,0) -> 1134 | K13: =J13/SUM($J$3:$J$141) -> 0.022434623 | L13: =K13*Inputs!$C$4 -> 628.4611 | M13: =IF(RANK(L13-INT(L13),$X$3:$X$141)+COUNTIF($X$3:X13,L13-INT(L13))-1<=Inputs!$C$4-SUMPRODUCT(INT($L$3:$L$141)),1,0) -> 0 | N13: =INT(L13)+M13 -> 628 | O13: 444 | P13: =IF(O13="","",N13-O13) -> 184 | X13: =L13-INT(L13) -> 0.46110402
A14: REO TRAVEL | C14: 92 | D14: 350 | E14: 417 | F14: 258 | G14: =SUM(D14:F14) -> 1025 | H14: =C14 -> 92 | I14: =MIN(MAX(H14,Inputs!$C$8),Inputs!$C$7) -> 92 | J14: =IF(I14>0,G14/I14*Inputs!$C$7,0) -> 1025 | K14: =J14/SUM($J$3:$J$141) -> 0.020278209 | L14: =K14*Inputs!$C$4 -> 568.05347 | M14: =IF(RANK(L14-INT(L14),$X$3:$X$141)+COUNTIF($X$3:X14,L14-INT(L14))-1<=Inputs!$C$4-SUMPRODUCT(INT($L$3:$L$141)),1,0) -> 0 | N14: =INT(L14)+M14 -> 568 | O14: 444 | P14: =IF(O14="","",N14-O14) -> 124 | X14: =L14-INT(L14) -> 0.053467036
... A73: POCKET TRAVEL | C73: 92 | D73: 66 | E73: 52 | F73: 13 | G73: =SUM(D73:F73) -> 131 | H73: =C73 -> 92 | I73: =MIN(MAX(H73,Inputs!$C$8),Inputs!$C$7) -> 92 | J73: =IF(I73>0,G73/I73*Inputs!$C$7,0) -> 131 | K73: =J73/SUM($J$3:$J$141) -> 0.002591654 | L73: =K73*Inputs!$C$4 -> 72.600004 | M73: =IF(RANK(L73-INT(L73),$X$3:$X$141)+COUNTIF($X$3:X73,L73-INT(L73))-1<=Inputs!$C$4-SUMPRODUCT(INT($L$3:$L$141)),1,0) -> 1 | N73: =INT(L73)+M73 -> 73 | O73: 111 | P73: =IF(O73="","",N73-O73) -> -38 | X73: =L73-INT(L73) -> 0.60000408
A74: LAFEMME | B74: 46290 | C74: 6 | D74: 0 | E74: 0 | F74: 19 | G74: =SUM(D74:F74) -> 19 | H74: =C74 -> 6 | I74: =MIN(MAX(H74,Inputs!$C$8),Inputs!$C$7) -> 14 | J74: =IF(I74>0,G74/I74*Inputs!$C$7,0) -> 124.85714 | K74: =J74/SUM($J$3:$J$141) -> 0.0024701261 | L74: =K74*Inputs!$C$4 -> 69.195642 | M74: =IF(RANK(L74-INT(L74),$X$3:$X$141)+COUNTIF($X$3:X74,L74-INT(L74))-1<=Inputs!$C$4-SUMPRODUCT(INT($L$3:$L$141)),1,0) -> 0 | N74: =INT(L74)+M74 -> 69 | O74: 0 | P74: =IF(O74="","",N74-O74) -> 69 | X74: =L74-INT(L74) -> 0.19564184
A75: SPARK | C75: 92 | D75: 47 | E75: 38 | F75: 32 | G75: =SUM(D75:F75) -> 117 | H75: =C75 -> 92 | I75: =MIN(MAX(H75,Inputs!$C$8),Inputs!$C$7) -> 92 | J75: =IF(I75>0,G75/I75*Inputs!$C$7,0) -> 117 | K75: =J75/SUM($J$3:$J$141) -> 0.0023146834 | L75: =K75*Inputs!$C$4 -> 64.841225 | M75: =IF(RANK(L75-INT(L75),$X$3:$X$141)+COUNTIF($X$3:X75,L75-INT(L75))-1<=Inputs!$C$4-SUMPRODUCT(INT($L$3:$L$141)),1,0) -> 1 | N75: =INT(L75)+M75 -> 65 | O75: 111 | P75: =IF(O75="","",N75-O75) -> -46 | X75: =L75-INT(L75) -> 0.84122502
A76: LAPTOP SLEEVE | C76: 90 | D76: 0 | E76: 3 | F76: 108 | G76: =SUM(D76:F76) -> 111 | H76: =C76 -> 90 | I76: =MIN(MAX(H76,Inputs!$C$8),Inputs!$C$7) -> 90 | J76: =IF(I76>0,G76/I76*Inputs!$C$7,0) -> 113.46667 | K76: =J76/SUM($J$3:$J$141) -> 0.0022447812 | L76: =K76*Inputs!$C$4 -> 62.883057 | M76: =IF(RANK(L76-INT(L76),$X$3:$X$141)+COUNTIF($X$3:X76,L76-INT(L76))-1<=Inputs!$C$4-SUMPRODUCT(INT($L$3:$L$141)),1,0) -> 1 | N76: =INT(L76)+M76 -> 63 | P76: =IF(O76="","",N76-O76) | X76: =L76-INT(L76) -> 0.88305697
A77: MINI SCHOOL | C77: 92 | D77: 40 | E77: 44 | F77: 29 | G77: =SUM(D77:F77) -> 113 | H77: =C77 -> 92 | I77: =MIN(MAX(H77,Inputs!$C$8),Inputs!$C$7) -> 92 | J77: =IF(I77>0,G77/I77*Inputs!$C$7,0) -> 113 | K77: =J77/SUM($J$3:$J$141) -> 0.0022355489 | L77: =K77*Inputs!$C$4 -> 62.624431 | M77: =IF(RANK(L77-INT(L77),$X$3:$X$141)+COUNTIF($X$3:X77,L77-INT(L77))-1<=Inputs!$C$4-SUMPRODUCT(INT($L$3:$L$141)),1,0) -> 1 | N77: =INT(L77)+M77 -> 63 | O77: 62 | P77: =IF(O77="","",N77-O77) -> 1 | X77: =L77-INT(L77) -> 0.624431
A78: TRAVOLTA | C78: 92 | D78: 41 | E78: 40 | F78: 24 | G78: =SUM(D78:F78) -> 105 | H78: =C78 -> 92 | I78: =MIN(MAX(H78,Inputs!$C$8),Inputs!$C$7) -> 92 | J78: =IF(I78>0,G78/I78*Inputs!$C$7,0) -> 105 | K78: =J78/SUM($J$3:$J$141) -> 0.0020772799 | L78: =K78*Inputs!$C$4 -> 58.190843 | M78: =IF(RANK(L78-INT(L78),$X$3:$X$141)+COUNTIF($X$3:X78,L78-INT(L78))-1<=Inputs!$C$4-SUMPRODUCT(INT($L$3:$L$141)),1,0) -> 0 | N78: =INT(L78)+M78 -> 58 | O78: 56 | P78: =IF(O78="","",N78-O78) -> 2 | X78: =L78-INT(L78) -> 0.19084296
A79: ZOEZI | C79: 92 | D79: 36 | E79: 36 | F79: 33 | G79: =SUM(D79:F79) -> 105 | H79: =C79 -> 92 | I79: =MIN(MAX(H79,Inputs!$C$8),Inputs!$C$7) -> 92 | J79: =IF(I79>0,G79/I79*Inputs!$C$7,0) -> 105 | K79: =J79/SUM($J$3:$J$141) -> 0.0020772799 | L79: =K79*Inputs!$C$4 -> 58.190843 | M79: =IF(RANK(L79-INT(L79),$X$3:$X$141)+COUNTIF($X$3:X79,L79-INT(L79))-1<=Inputs!$C$4-SUMPRODUCT(INT($L$3:$L$141)),1,0) -> 0 | N79: =INT(L79)+M79 -> 58 | O79: 132 | P79: =IF(O79="","",N79-O79) -> -74 | X79: =L79-INT(L79) -> 0.19084296
A80: NALA | C80: 92 | D80: 44 | E80: 32 | F80: 22 | G80: =SUM(D80:F80) -> 98 | H80: =C80 -> 92 | I80: =MIN(MAX(H80,Inputs!$C$8),Inputs!$C$7) -> 92 | J80: =IF(I80>0,G80/I80*Inputs!$C$7,0) -> 98 | K80: =J80/SUM($J$3:$J$141) -> 0.0019387946 | L80: =K80*Inputs!$C$4 -> 54.311453 | M80: =IF(RANK(L80-INT(L80),$X$3:$X$141)+COUNTIF($X$3:X80,L80-INT(L80))-1<=Inputs!$C$4-SUMPRODUCT(INT($L$3:$L$141)),1,0) -> 0 | N80: =INT(L80)+M80 -> 54 | O80: 33 | P80: =IF(O80="","",N80-O80) -> 21 | X80: =L80-INT(L80) -> 0.31145343
A81: ZELUS | C81: 92 | D81: 40 | E81: 34 | F81: 22 | G81: =SUM(D81:F81) -> 96 | H81: =C81 -> 92 | I81: =MIN(MAX(H81,Inputs!$C$8),Inputs!$C$7) -> 92 | J81: =IF(I81>0,G81/I81*Inputs!$C$7,0) -> 96 | K81: =J81/SUM($J$3:$J$141) -> 0.0018992274 | L81: =K81*Inputs!$C$4 -> 53.203056 | M81: =IF(RANK(L81-INT(L81),$X$3:$X$141)+COUNTIF($X$3:X81,L81-INT(L81))-1<=Inputs!$C$4-SUMPRODUCT(INT($L$3:$L$141)),1,0) -> 0 | N81: =INT(L81)+M81 -> 53 | O81: 39 | P81: =IF(O81="","",N81-O81) -> 14 | X81: =L81-INT(L81) -> 0.20305642
A82: LANKA | C82: 92 | D82: 35 | E82: 28 | F82: 31 | G82: =SUM(D82:F82) -> 94 | H82: =C82 -> 92 | I82: =MIN(MAX(H82,Inputs!$C$8),Inputs!$C$7) -> 92 | J82: =IF(I82>0,G82/I82*Inputs!$C$7,0) -> 94 | K82: =J82/SUM($J$3:$J$141) -> 0.0018596601 | L82: =K82*Inputs!$C$4 -> 52.094659 | M82: =IF(RANK(L82-INT(L82),$X$3:$X$141)+COUNTIF($X$3:X82,L82-INT(L82))-1<=Inputs!$C$4-SUMPRODUCT(INT($L$3:$L$141)),1,0) -> 0 | N82: =INT(L82)+M82 -> 52 | O82: 56 | P82: =IF(O82="","",N82-O82) -> -4 | X82: =L82-INT(L82) -> 0.094659416
A83: MINI MANBAG | C83: 92 | D83: 46 | E83: 26 | F83: 22 | G83: =SUM(D83:F83) -> 94 | H83: =C83 -> 92 | I83: =MIN(MAX(H83,Inputs!$C$8),Inputs!$C$7) -> 92 | J83: =IF(I83>0,G83/I83*Inputs!$C$7,0) -> 94 | K83: =J83/SUM($J$3:$J$141) -> 0.0018596601 | L83: =K83*Inputs!$C$4 -> 52.094659 | M83: =IF(RANK(L83-INT(L83),$X$3:$X$141)+COUNTIF($X$3:X83,L83-INT(L83))-1<=Inputs!$C$4-SUMPRODUCT(INT($L$3:$L$141)),1,0) -> 0 | N83: =INT(L83)+M83 -> 52 | O83: 30 | P83: =IF(O83="","",N83-O83) -> 22 | X83: =L83-INT(L83) -> 0.094659416
A84: ZENO | C84: 92 | D84: 49 | E84: 24 | F84: 20 | G84: =SUM(D84:F84) -> 93 | H84: =C84 -> 92 | I84: =MIN(MAX(H84,Inputs!$C$8),Inputs!$C$7) -> 92 | J84: =IF(I84>0,G84/I84*Inputs!$C$7,0) -> 93 | K84: =J84/SUM($J$3:$J$141) -> 0.0018398765 | L84: =K84*Inputs!$C$4 -> 51.540461 | M84: =IF(RANK(L84-INT(L84),$X$3:$X$141)+COUNTIF($X$3:X84,L84-INT(L84))-1<=Inputs!$C$4-SUMPRODUCT(INT($L$3:$L$141)),1,0) -> 1 | N84: =INT(L84)+M84 -> 52 | O84: 28 | P84: =IF(O84="","",N84-O84) -> 24 | X84: =L84-INT(L84) -> 0.54046091
A85: ZURI | C85: 92 | D85: 27 | E85: 30 | F85: 26 | G85: =SUM(D85:F85) -> 83 | H85: =C85 -> 92 | I85: =MIN(MAX(H85,Inputs!$C$8),Inputs!$C$7) -> 92 | J85: =IF(I85>0,G85/I85*Inputs!$C$7,0) -> 83 | K85: =J85/SUM($J$3:$J$141) -> 0.0016420403 | L85: =K85*Inputs!$C$4 -> 45.998476 | M85: =IF(RANK(L85-INT(L85),$X$3:$X$141)+COUNTIF($X$3:X85,L85-INT(L85))-1<=Inputs!$C$4-SUMPRODUCT(INT($L$3:$L$141)),1,0) -> 1 | N85: =INT(L85)+M85 -> 46 | P85: =IF(O85="","",N85-O85) | X85: =L85-INT(L85) -> 0.99847587
A86: UMBRA | C86: 92 | D86: 31 | E86: 15 | F86: 31 | G86: =SUM(D86:F86) -> 77 | H86: =C86 -> 92 | I86: =MIN(MAX(H86,Inputs!$C$8),Inputs!$C$7) -> 92 | J86: =IF(I86>0,G86/I86*Inputs!$C$7,0) -> 77 | K86: =J86/SUM($J$3:$J$141) -> 0.0015233386 | L86: =K86*Inputs!$C$4 -> 42.673285 | M86: =IF(RANK(L86-INT(L86),$X$3:$X$141)+COUNTIF($X$3:X86,L86-INT(L86))-1<=Inputs!$C$4-SUMPRODUCT(INT($L$3:$L$141)),1,0) -> 1 | N86: =INT(L86)+M86 -> 43 | O86: 22 | P86: =IF(O86="","",N86-O86) -> 21 | X86: =L86-INT(L86) -> 0.67328484
A87: ESMERALDA | C87: 92 | D87: 5 | E87: 32 | F87: 38 | G87: =SUM(D87:F87) -> 75 | H87: =C87 -> 92 | I87: =MIN(MAX(H87,Inputs!$C$8),Inputs!$C$7) -> 92 | J87: =IF(I87>0,G87/I87*Inputs!$C$7,0) -> 75 | K87: =J87/SUM($J$3:$J$141) -> 0.0014837714 | L87: =K87*Inputs!$C$4 -> 41.564888 | M87: =IF(RANK(L87-INT(L87),$X$3:$X$141)+COUNTIF($X$3:X87,L87-INT(L87))-1<=Inputs!$C$4-SUMPRODUCT(INT($L$3:$L$141)),1,0) -> 1 | N87: =INT(L87)+M87 -> 42 | O87: 56 | P87: =IF(O87="","",N87-O87) -> -14 | X87: =L87-INT(L87) -> 0.56488783
A88: CESS | C88: 92 | D88: 25 | E88: 18 | F88: 26 | G88: =SUM(D88:F88) -> 69 | H88: =C88 -> 92 | I88: =MIN(MAX(H88,Inputs!$C$8),Inputs!$C$7) -> 92 | J88: =IF(I88>0,G88/I88*Inputs!$C$7,0) -> 69 | K88: =J88/SUM($J$3:$J$141) -> 0.0013650697 | L88: =K88*Inputs!$C$4 -> 38.239697 | M88: =IF(RANK(L88-INT(L88),$X$3:$X$141)+COUNTIF($X$3:X88,L88-INT(L88))-1<=Inputs!$C$4-SUMPRODUCT(INT($L$3:$L$141)),1,0) -> 0 | N88: =INT(L88)+M88 -> 38 | O88: 11 | P88: =IF(O88="","",N88-O88) -> 27 | X88: =L88-INT(L88) -> 0.23969681
A89: BELLO | C89: 92 | D89: 23 | E89: 17 | F89: 22 | G89: =SUM(D89:F89) -> 62 | H89: =C89 -> 92 | I89: =MIN(MAX(H89,Inputs!$C$8),Inputs!$C$7) -> 92 | J89: =IF(I89>0,G89/I89*Inputs!$C$7,0) -> 62 | K89: =J89/SUM($J$3:$J$141) -> 0.0012265843 | L89: =K89*Inputs!$C$4 -> 34.360307 | M89: =IF(RANK(L89-INT(L89),$X$3:$X$141)+COUNTIF($X$3:X89,L89-INT(L89))-1<=Inputs!$C$4-SUMPRODUCT(INT($L$3:$L$141)),1,0) -> 0 | N89: =INT(L89)+M89 -> 34 | O89: 17 | P89: =IF(O89="","",N89-O89) -> 17 | X89: =L89-INT(L89) -> 0.36030727
A90: CODE 9 | C90: 92 | D90: 29 | E90: 16 | F90: 17 | G90: =SUM(D90:F90) -> 62 | H90: =C90 -> 92 | I90: =MIN(MAX(H90,Inputs!$C$8),Inputs!$C$7) -> 92 | J90: =IF(I90>0,G90/I90*Inputs!$C$7,0) -> 62 | K90: =J90/SUM($J$3:$J$141) -> 0.0012265843 | L90: =K90*Inputs!$C$4 -> 34.360307 | M90: =IF(RANK(L90-INT(L90),$X$3:$X$141)+COUNTIF($X$3:X90,L90-INT(L90))-1<=Inputs!$C$4-SUMPRODUCT(INT($L$3:$L$141)),1,0) -> 0 | N90: =INT(L90)+M90 -> 34 | O90: 39 | P90: =IF(O90="","",N90-O90) -> -5 | X90: =L90-INT(L90) -> 0.36030727
A91: SATCHEL | C91: 92 | D91: 25 | E91: 26 | F91: 7 | G91: =SUM(D91:F91) -> 58 | H91: =C91 -> 92 | I91: =MIN(MAX(H91,Inputs!$C$8),Inputs!$C$7) -> 92 | J91: =IF(I91>0,G91/I91*Inputs!$C$7,0) -> 58 | K91: =J91/SUM($J$3:$J$141) -> 0.0011474499 | L91: =K91*Inputs!$C$4 -> 32.143513 | M91: =IF(RANK(L91-INT(L91),$X$3:$X$141)+COUNTIF($X$3:X91,L91-INT(L91))-1<=Inputs!$C$4-SUMPRODUCT(INT($L$3:$L$141)),1,0) -> 0 | N91: =INT(L91)+M91 -> 32 | O91: 23 | P91: =IF(O91="","",N91-O91) -> 9 | X91: =L91-INT(L91) -> 0.14351326
A92: MODERN TRAVEL | C92: 13 | D92: 8 | E92: 0 | F92: 0 | G92: =SUM(D92:F92) -> 8 | H92: =C92 -> 13 | I92: =MIN(MAX(H92,Inputs!$C$8),Inputs!$C$7) -> 14 | J92: =IF(I92>0,G92/I92*Inputs!$C$7,0) -> 52.571429 | K92: =J92/SUM($J$3:$J$141) -> 0.0010400531 | L92: =K92*Inputs!$C$4 -> 29.135007 | M92: =IF(RANK(L92-INT(L92),$X$3:$X$141)+COUNTIF($X$3:X92,L92-INT(L92))-1<=Inputs!$C$4-SUMPRODUCT(INT($L$3:$L$141)),1,0) -> 0 | N92: =INT(L92)+M92 -> 29 | O92: 0 | P92: =IF(O92="","",N92-O92) -> 29 | X92: =L92-INT(L92) -> 0.13500709
A93: JAYDEN MAN | C93: 92 | D93: 31 | E93: 8 | F93: 11 | G93: =SUM(D93:F93) -> 50 | H93: =C93 -> 92 | I93: =MIN(MAX(H93,Inputs!$C$8),Inputs!$C$7) -> 92 | J93: =IF(I93>0,G93/I93*Inputs!$C$7,0) -> 50 | K93: =J93/SUM($J$3:$J$141) -> 0.00098918092 | L93: =K93*Inputs!$C$4 -> 27.709925 | M93: =IF(RANK(L93-INT(L93),$X$3:$X$141)+COUNTIF($X$3:X93,L93-INT(L93))-1<=Inputs!$C$4-SUMPRODUCT(INT($L$3:$L$141)),1,0) -> 1 | N93: =INT(L93)+M93 -> 28 | O93: 105 | P93: =IF(O93="","",N93-O93) -> -77 | X93: =L93-INT(L93) -> 0.70992522
A94: MANDY HB | C94: 92 | D94: 19 | E94: 17 | F94: 13 | G94: =SUM(D94:F94) -> 49 | H94: =C94 -> 92 | I94: =MIN(MAX(H94,Inputs!$C$8),Inputs!$C$7) -> 92 | J94: =IF(I94>0,G94/I94*Inputs!$C$7,0) -> 49 | K94: =J94/SUM($J$3:$J$141) -> 0.00096939731 | L94: =K94*Inputs!$C$4 -> 27.155727 | M94: =IF(RANK(L94-INT(L94),$X$3:$X$141)+COUNTIF($X$3:X94,L94-INT(L94))-1<=Inputs!$C$4-SUMPRODUCT(INT($L$3:$L$141)),1,0) -> 0 | N94: =INT(L94)+M94 -> 27 | O94: 33 | P94: =IF(O94="","",N94-O94) -> -6 | X94: =L94-INT(L94) -> 0.15572672
A95: ARLO MAN BAG | C95: 92 | D95: 5 | E95: 14 | F95: 26 | G95: =SUM(D95:F95) -> 45 | H95: =C95 -> 92 | I95: =MIN(MAX(H95,Inputs!$C$8),Inputs!$C$7) -> 92 | J95: =IF(I95>0,G95/I95*Inputs!$C$7,0) -> 45 | K95: =J95/SUM($J$3:$J$141) -> 0.00089026283 | L95: =K95*Inputs!$C$4 -> 24.938933 | M95: =IF(RANK(L95-INT(L95),$X$3:$X$141)+COUNTIF($X$3:X95,L95-INT(L95))-1<=Inputs!$C$4-SUMPRODUCT(INT($L$3:$L$141)),1,0) -> 1 | N95: =INT(L95)+M95 -> 25 | O95: 11 | P95: =IF(O95="","",N95-O95) -> 14 | X95: =L95-INT(L95) -> 0.9389327
A96: NOVA | C96: 92 | D96: 22 | E96: 11 | F96: 4 | G96: =SUM(D96:F96) -> 37 | H96: =C96 -> 92 | I96: =MIN(MAX(H96,Inputs!$C$8),Inputs!$C$7) -> 92 | J96: =IF(I96>0,G96/I96*Inputs!$C$7,0) -> 37 | K96: =J96/SUM($J$3:$J$141) -> 0.00073199388 | L96: =K96*Inputs!$C$4 -> 20.505345 | M96: =IF(RANK(L96-INT(L96),$X$3:$X$141)+COUNTIF($X$3:X96,L96-INT(L96))-1<=Inputs!$C$4-SUMPRODUCT(INT($L$3:$L$141)),1,0) -> 0 | N96: =INT(L96)+M96 -> 20 | O96: 0 | P96: =IF(O96="","",N96-O96) -> 20 | X96: =L96-INT(L96) -> 0.50534466
A97: WANDER LUXE | C97: 92 | D97: 9 | E97: 19 | F97: 8 | G97: =SUM(D97:F97) -> 36 | H97: =C97 -> 92 | I97: =MIN(MAX(H97,Inputs!$C$8),Inputs!$C$7) -> 92 | J97: =IF(I97>0,G97/I97*Inputs!$C$7,0) -> 36 | K97: =J97/SUM($J$3:$J$141) -> 0.00071221027 | L97: =K97*Inputs!$C$4 -> 19.951146 | M97: =IF(RANK(L97-INT(L97),$X$3:$X$141)+COUNTIF($X$3:X97,L97-INT(L97))-1<=Inputs!$C$4-SUMPRODUCT(INT($L$3:$L$141)),1,0) -> 1 | N97: =INT(L97)+M97 -> 20 | O97: 22 | P97: =IF(O97="","",N97-O97) -> -2 | X97: =L97-INT(L97) -> 0.95114616
... A141: SCARLET | C141: 73 | D141: 0 | E141: 0 | F141: 1 | G141: =SUM(D141:F141) -> 1 | H141: =C141 -> 73 | I141: =MIN(MAX(H141,Inputs!$C$8),Inputs!$C$7) -> 73 | J141: =IF(I141>0,G141/I141*Inputs!$C$7,0) -> 1.260274 | K141: =J141/SUM($J$3:$J$141) -> 2.4932779e-05 | L141: =K141*Inputs!$C$4 -> 0.69844195 | M141: =IF(RANK(L141-INT(L141),$X$3:$X$141)+COUNTIF($X$3:X141,L141-INT(L141))-1<=Inputs!$C$4-SUMPRODUCT(INT($L$3:$L$141)),1,0) -> 1 | N141: =INT(L141)+M141 -> 1 | O141: 0 | P141: =IF(O141="","",N141-O141) -> 1 | X141: =L141-INT(L141) -> 0.69844195
...
